Workbook

Sheet Sheet1
A1: EmpId | B1: EmpName | C1: Designation | D1: PresentDays | E1: AbsentDays | F1: LeaveDays | G1: OTDays | H1: Days
A2: 10000 | B2: Jitendra Kushwaha | C2: Patroller | D2: 30 | E2: 0 | F2: 0 | G2: 0 | H2: =D2+G2 -> 30
A3: 10001 | B3: Indra Pratap Singh | C3: Patroller | D3: 30 | E3: 0 | F3: 0 | G3: 0 | H3: =D3+G3 -> 30
A4: 10002 | B4: Alok Kumar | C4: Patroller | D4: 30 | E4: 0 | F4: 0 | G4: 0 | H4: =D4+G4 -> 30
A5: 10003 | B5: Dileep Kumar | C5: Patroller | D5: 30 | E5: 0 | F5: 0 | G5: 0 | H5: =D5+G5 -> 30
A6: 10004 | B6: Brijendra Singh | C6: Patroller | D6: 30 | E6: 0 | F6: 0 | G6: 0 | H6: =D6+G6 -> 30
A7: 10005 | B7: Bharat Prasad | C7: Patroller | D7: 30 | E7: 0 | F7: 0 | G7: 0 | H7: =D7+G7 -> 30
A8: 10006 | B8: Ganesh | C8: Patroller | D8: 30 | E8: 0 | F8: 0 | G8: 0 | H8: =D8+G8 -> 30
A9: 10007 | B9: Digvijay Singh | C9: Patroller | D9: 30 | E9: 0 | F9: 0 | G9: 0 | H9: =D9+G9 -> 30
A10: 10008 | B10: Anoop Kumar | C10: Patroller | D10: 30 | E10: 0 | F10: 0 | G10: 0 | H10: =D10+G10 -> 30
A11: 10009 | B11: Jagdeesh Kumhar | C11: Patroller | D11: 30 | E11: 0 | F11: 0 | G11: 0 | H11: =D11+G11 -> 30
A12: 10010 | B12: Kailash Kushwaha | C12: Patroller | D12: 30 | E12: 0 | F12: 0 | G12: 0 | H12: =D12+G12 -> 30
A13: 10011 | B13: Satyam Kumar | C13: Patroller | D13: 30 | E13: 0 | F13: 0 | G13: 0 | H13: =D13+G13 -> 30
... A188: 8210 | B188: Suresh Dharmdas Patil | C188: Site Caretaker | D188: 30 | E188: 0 | F188: 0 | G188: 0 | H188: =D188+G188 -> 30
A189: 8269 | B189: Bacchan Lala | C189: 0 | D189: 30 | E189: 0 | F189: 0 | G189: 0 | H189: =D189+G189 -> 30
A190: 8289 | B190: Kuldeep Singh | C190: IT Head | D190: 30 | E190: 0 | F190: 0 | G190: 0 | H190: =D190+G190 -> 30
A191: 8339 | B191: Nagraj A Naik | C191: Rigger | D191: 30 | E191: 0 | F191: 0 | G191: 0 | H191: =D191+G191 -> 30
A192: 8348 | B192: Amrut Madhu Gavit | C192: Labour | D192: 30 | E192: 0 | F192: 0 | G192: 0 | H192: =D192+G192 -> 30
A193: 8349 | B193: Dipak Santosh Dhangar | C193: Rigger | D193: 30 | E193: 0 | F193: 0 | G193: 0 | H193: =D193+G193 -> 30
A194: 8374 | B194: Ankush Bhardwaj | C194: Manager | D194: 30 | E194: 0 | F194: 0 | G194: 0 | H194: =D194+G194 -> 30
A195: 8385 | B195: Anil Sudhaker Jagtap | C195: Rigger | D195: 30 | E195: 0 | F195: 0 | G195: 0 | H195: =D195+G195 -> 30
A196: 8395 | B196: Vikarant Ramdas Meshram | C196: Labour | D196: 30 | E196: 0 | F196: 0 | G196: 0 | H196: =D196+G196 -> 30
A197: 8396 | B197: Snehal Devanand Meshram | C197: Rigger | D197: 30 | E197: 0 | F197: 0 | G197: 0 | H197: =D197+G197 -> 30
A198: 8411 | B198: Ambadas Nanasaheb Dhanwate | C198: Rigger | D198: 30 | E198: 0 | F198: 0 | G198: 0 | H198: =D198+G198 -> 30
A199: 8458 | B199: Chauhan Premjibhai Devsibhai | C199: Labour | D199: 30 | E199: 0 | F199: 0 | G199: 0 | H199: =D199+G199 -> 30
A200: 8470 | B200: Mangesh Sahadevrao Chavhan | C200: Labour | D200: 30 | E200: 0 | F200: 0 | G200: 0 | H200: =D200+G200 -> 30
A201: 8473 | B201: Rohit Harishchandra Patil | C201: Labour | D201: 27 | E201: 0 | F201: 0 | G201: 0 | H201: =D201+G201 -> 27
... A227: 9561 | B227: Anmol Saini | C227: IOS Developer | D227: 29 | E227: 0 | F227: 1 | G227: 0 | H227: =D227+G227 -> 29
A228: 9617 | B228: Rahul Kaushik | C228: 0 | D228: 22 | E228: 0 | F228: 0 | G228: 0 | H228: =D228+G228 -> 22
A229: 9624 | B229: Mohit Agrawal | C229: Inside Sale Officer | D229: 30 | E229: 0 | F229: 0 | G229: 0 | H229: =D229+G229 -> 30
A230: 9625 | B230: Deepak Kumar | C230: Project Lead | D230: 30 | E230: 0 | F230: 0 | G230: 0 | H230: =D230+G230 -> 30
A231: 9629 | B231: Gaurav Saxena | C231: Project Manager | D231: 30 | E231: 0 | F231: 0 | G231: 0 | H231: =D231+G231 -> 30
A232: 9648 | B232: Vijay Kumar | C232: Centre Project Coordinator | D232: 30 | E232: 0 | F232: 0 | G232: 0 | H232: =D232+G232 -> 30
A233: 9663 | B233: Jagvir Singh | C233: Assistant Manager | D233: 30 | E233: 0 | F233: 0 | G233: 0 | H233: =D233+G233 -> 30
A234: 9675 | B234: Soni Jain | C234: Finance Controler | D234: 30 | E234: 0 | F234: 0 | G234: 0 | H234: =D234+G234 -> 30
A235: 9677 | B235: Sajal Halder | C235: Senior Superviser | D235: 30 | E235: 0 | F235: 0 | G235: 0 | H235: =D235+G235 -> 30
A236: 9680 | B236: Anil Kumar | C236: Patroller | D236: 30 | E236: 0 | F236: 0 | G236: 0 | H236: =D236+G236 -> 30
A237: 9681 | B237: Krishana Kumar | C237: Patroller | D237: 30 | E237: 0 | F237: 0 | G237: 0 | H237: =D237+G237 -> 30
A238: 9682 | B238: Pravesh Katiyar | C238: Patroller | D238: 30 | E238: 0 | F238: 0 | G238: 0 | H238: =D238+G238 -> 30
A239: 9683 | B239: Gangaram | C239: Patroller | D239: 30 | E239: 0 | F239: 0 | G239: 0 | H239: =D239+G239 -> 30
...

Sheet sep
A1: Code | B1: Employee | C1: Designation | D1: Present | E1: Absent | F1: Leave | G1: Over Time | H1: Total Days
A2: 10002 | B2: Alok Kumar | C2: Patroller | D2: 30 | E2: 0 | F2: 0 | G2: 0 | H2: 30 | I2: =VLOOKUP(A2,Sheet2!A4:B1102,2,0) -> Alok Kumar
A3: 10013 | B3: Anil Singh | C3: Patroller | D3: 30 | E3: 0 | F3: 0 | G3: 0 | H3: 30 | I3: =VLOOKUP(A3,Sheet2!A15:B1113,2,0) -> Anil Singh
A4: 10008 | B4: Anoop Kumar | C4: Patroller | D4: 30 | E4: 0 | F4: 0 | G4: 0 | H4: 30 | I4: =VLOOKUP(A4,Sheet2!A10:B1108,2,0) -> Anoop Kumar
A5: 10005 | B5: Bharat Prasad | C5: Patroller | D5: 30 | E5: 0 | F5: 0 | G5: 0 | H5: 30 | I5: =VLOOKUP(A5,Sheet2!A7:B1105,2,0) -> Bharat Prasad
A6: 10004 | B6: Brijendra Singh | C6: Patroller | D6: 30 | E6: 0 | F6: 0 | G6: 0 | H6: 30 | I6: =VLOOKUP(A6,Sheet2!A6:B1104,2,0) -> Brijendra Singh
A7: 10007 | B7: Digvijay Singh | C7: Patroller | D7: 30 | E7: 0 | F7: 0 | G7: 0 | H7: 30 | I7: =VLOOKUP(A7,Sheet2!A9:B1107,2,0) -> Digvijay Singh
A8: 10003 | B8: Dileep Kumar | C8: Patroller | D8: 30 | E8: 0 | F8: 0 | G8: 0 | H8: 30 | I8: =VLOOKUP(A8,Sheet2!A5:B1103,2,0) -> Dileep Kumar
A9: 10017 | B9: Dinesh Pal | C9: Patroller | D9: 30 | E9: 0 | F9: 0 | G9: 0 | H9: 30 | I9: =VLOOKUP(A9,Sheet2!A19:B1117,2,0) -> Dinesh Pal
A10: 10006 | B10: Ganesh | C10: Patroller | D10: 30 | E10: 0 | F10: 0 | G10: 0 | H10: 30 | I10: =VLOOKUP(A10,Sheet2!A8:B1106,2,0) -> Ganesh
A11: 10015 | B11: Gyan Singh | C11: Patroller | D11: 30 | E11: 0 | F11: 0 | G11: 0 | H11: 30 | I11: =VLOOKUP(A11,Sheet2!A17:B1115,2,0) -> Gyan Singh
A12: 10001 | B12: Indra Pratap Singh | C12: Patroller | D12: 30 | E12: 0 | F12: 0 | G12: 0 | H12: 30 | I12: =VLOOKUP(A12,Sheet2!A3:B1101,2,0) -> Indra Pratap Singh
A13: 10009 | B13: Jagdeesh Kumhar | C13: Patroller | D13: 30 | E13: 0 | F13: 0 | G13: 0 | H13: 30 | I13: =VLOOKUP(A13,Sheet2!A11:B1109,2,0) -> Jagdeesh Kumhar
A14: 10000 | B14: Jitendra Kushwaha | C14: Patroller | D14: 30 | E14: 0 | F14: 0 | G14: 0 | H14: 30 | I14: =VLOOKUP(A14,Sheet2!A2:B1100,2,0) -> Jitendra Kushwaha
A15: 10010 | B15: Kailash Kushwaha | C15: Patroller | D15: 30 | E15: 0 | F15: 0 | G15: 0 | H15: 30 | I15: =VLOOKUP(A15,Sheet2!A12:B1110,2,0) -> Kailash Kushwaha
A16: 10023 | B16: Kailash Singh | C16: Patroller | D16: 30 | E16: 0 | F16: 0 | G16: 0 | H16: 30 | I16: =VLOOKUP(A16,Sheet2!A24:B1122,2,0) -> Kailash Singh
A17: 10012 | B17: Manoj | C17: Patroller | D17: 30 | E17: 0 | F17: 0 | G17: 0 | H17: 30 | I17: =VLOOKUP(A17,Sheet2!A14:B1112,2,0) -> Manoj
A18: 10016 | B18: Pinku | C18: Patroller | D18: 30 | E18: 0 | F18: 0 | G18: 0 | H18: 30 | I18: =VLOOKUP(A18,Sheet2!A18:B1116,2,0) -> Pinku
A19: 10018 | B19: Prashant Pal | C19: Patroller | D19: 30 | E19: 0 | F19: 0 | G19: 0 | H19: 30 | I19: =VLOOKUP(A19,Sheet2!A20:B1118,2,0) -> Prashant Pal
A20: 10019 | B20: Rajesh Pal | C20: Patroller | D20: 30 | E20: 0 | F20: 0 | G20: 0 | H20: 30 | I20: =VLOOKUP(A20,Sheet2!A21:B1119,2,0) -> Rajesh Pal
A21: 10014 | B21: Ranjdeep Singh Bundela | C21: Patroller | D21: 30 | E21: 0 | F21: 0 | G21: 0 | H21: 30 | I21: =VLOOKUP(A21,Sheet2!A16:B1114,2,0) -> Ranjdeep Singh Bundela
A22: 10020 | B22: Ravindra Kumar Vishwakarma | C22: Patroller | D22: 30 | E22: 0 | F22: 0 | G22: 0 | H22: 30 | I22: =VLOOKUP(A22,Sheet2!A22:B1120,2,0) -> Ravindra Kumar Vishwakarma
A23: 10011 | B23: Satyam Kumar | C23: Patroller | D23: 30 | E23: 0 | F23: 0 | G23: 0 | H23: 30 | I23: =VLOOKUP(A23,Sheet2!A13:B1111,2,0) -> Satyam Kumar
A24: 10022 | B24: Shailendra Kumar Yadav | C24: Patroller | D24: 30 | E24: 0 | F24: 0 | G24: 0 | H24: 30 | I24: =VLOOKUP(A24,Sheet2!A23:B1121,2,0) -> Shailendra Kumar Yadav
A25: 10024 | B25: Shaik Babavali | C25: Patroller | D25: 30 | E25: 0 | F25: 0 | G25: 0 | H25: 30 | I25: =VLOOKUP(A25,Sheet2!A2:B1100,2,0) -> #N/A | J25: =VLOOKUP(A25,Sheet2!A2:C1100,2,0) -> #N/A
A26: 10025 | B26: Nagularapu Nagendra | C26: Patroller | D26: 30 | E26: 0 | F26: 0 | G26: 0 | H26: 30 | I26: =VLOOKUP(A26,Sheet2!A2:B1100,2,0) -> #N/A | J26: =VLOOKUP(A26,Sheet2!A3:C1101,2,0) -> #N/A
A27: 10026 | B27: Thippanaik | C27: Patroller | D27: 30 | E27: 0 | F27: 0 | G27: 0 | H27: 30 | I27: =VLOOKUP(A27,Sheet2!A2:B1100,2,0) -> #N/A | J27: =VLOOKUP(A27,Sheet2!A4:C1102,2,0) -> #N/A
A28: 10027 | B28: Vuddandam Eswaraiah | C28: Patroller | D28: 30 | E28: 0 | F28: 0 | G28: 0 | H28: 30 | I28: =VLOOKUP(A28,Sheet2!A3:B1101,2,0) -> #N/A | J28: =VLOOKUP(A28,Sheet2!A5:C1103,2,0) -> #N/A
A29: 10028 | B29: Gali Siva Sankar Reddy | C29: Patroller | D29: 30 | E29: 0 | F29: 0 | G29: 0 | H29: 30 | I29: =VLOOKUP(A29,Sheet2!A4:B1102,2,0) -> #N/A | J29: =VLOOKUP(A29,Sheet2!A6:C1104,2,0) -> #N/A
A30: 10029 | B30: Jetti Suresh | C30: Patroller | D30: 30 | E30: 0 | F30: 0 | G30: 0 | H30: 30 | I30: =VLOOKUP(A30,Sheet2!A5:B1103,2,0) -> #N/A | J30: =VLOOKUP(A30,Sheet2!A7:C1105,2,0) -> #N/A
A31: 10030 | B31: M Damodaram | C31: Patroller | D31: 30 | E31: 0 | F31: 0 | G31: 0 | H31: 30 | I31: =VLOOKUP(A31,Sheet2!A6:B1104,2,0) -> #N/A | J31: =VLOOKUP(A31,Sheet2!A8:C1106,2,0) -> #N/A
A32: 10031 | B32: Mitta Gurumurthy | C32: Patroller | D32: 30 | E32: 0 | F32: 0 | G32: 0 | H32: 30 | I32: =VLOOKUP(A32,Sheet2!A7:B1105,2,0) -> #N/A | J32: =VLOOKUP(A32,Sheet2!A9:C1107,2,0) -> #N/A
A33: 10032 | B33: Pagadala Shabaresh | C33: Patroller | D33: 30 | E33: 0 | F33: 0 | G33: 0 | H33: 30 | I33: =VLOOKUP(A33,Sheet2!A8:B1106,2,0) -> #N/A | J33: =VLOOKUP(A33,Sheet2!A10:C1108,2,0) -> #N/A
A34: 10033 | B34: Basineni Maheswar | C34: Patroller | D34: 30 | E34: 0 | F34: 0 | G34: 0 | H34: 30 | I34: =VLOOKUP(A34,Sheet2!A9:B1107,2,0) -> #N/A | J34: =VLOOKUP(A34,Sheet2!A11:C1109,2,0) -> #N/A
A35: 10034 | B35: V Eswarappa | C35: Patroller | D35: 30 | E35: 0 | F35: 0 | G35: 0 | H35: 30 | I35: =VLOOKUP(A35,Sheet2!A10:B1108,2,0) -> #N/A | J35: =VLOOKUP(A35,Sheet2!A12:C1110,2,0) -> #N/A
A36: 10035 | B36: Anandala Ravindra | C36: Patroller | D36: 30 | E36: 0 | F36: 0 | G36: 0 | H36: 30 | I36: =VLOOKUP(A36,Sheet2!A11:B1109,2,0) -> #N/A | J36: =VLOOKUP(A36,Sheet2!A13:C1111,2,0) -> #N/A
A37: 10036 | B37: Golla Nagendra | C37: Patroller | D37: 30 | E37: 0 | F37: 0 | G37: 0 | H37: 30 | I37: =VLOOKUP(A37,Sheet2!A12:B1110,2,0) -> #N/A | J37: =VLOOKUP(A37,Sheet2!A14:C1112,2,0) -> #N/A
A38: 10037 | B38: D B Rama Krishna | C38: Patroller | D38: 30 | E38: 0 | F38: 0 | G38: 0 | H38: 30 | I38: =VLOOKUP(A38,Sheet2!A13:B1111,2,0) -> #N/A | J38: =VLOOKUP(A38,Sheet2!A15:C1113,2,0) -> #N/A
... A939: 9999 | B939: Pradeep Kumar | C939: Patroller | D939: 30 | E939: 0 | F939: 0 | G939: 0 | H939: 30 | I939: =VLOOKUP(A939,Sheet2!A914:B2012,2,0) -> #N/A | J939: =VLOOKUP(A939,Sheet2!A916:C2014,2,0) -> #N/A
A940: TR-1000 | B940: Vikash Sharma | C940: Electrician | D940: 30 | E940: 0 | F940: 0 | G940: 0 | H940: 30 | I940: =VLOOKUP(A940,Sheet2!A915:B2013,2,0) -> #N/A | J940: =VLOOKUP(A940,Sheet2!A917:C2015,2,0) -> #N/A
...

Sheet Sheet2
A1: Empoyee ID | B1: Employee Name | C1: Father's Name | D1: Mother's Name | E1: Da te of Birth | F1: Address | G1: City Name | H1: Mobile | J1: Email | K1: Gender | L1: Date of Joining | M1: Category | N1: Department | O1: Designation | P1: Employee Type | Q1: Grade | R1: Is Active | S1: HOD | T1: Manager ID | U1: Reporting Manager | V1: UAN No | W1: ESI NO | X1: PAN | Y1: Aadhaar No | Z1: Personal Email | AA1: Bank A/c No | AB1: Bank Name | AC1: Bank Branch | AD1: IFSC Code | AE1: Emergency Contact Person | AF1: Relarion with Employee | AG1: Emergency Contact No | AH1: Medical Card No | AI1: Blood Group | AJ1: Nominee | AK1: login ID | AL1: Role Id | AM1: Is Mobile Mark Attendace | AN1: Is Mobile get auto Attendace | AO1: Is Get mobile Log
A2: 10000 | B2: Jitendra Kushwaha | C2: Prmand Kushwaha | E2: 01/Jul/1992 | F2: 892, Datia Gate, Kotwali, Jhanshi, Uttar Pradesh 284001 | G2: Kanpur | H2: 7007568442 | I2: =VLOOKUP(A2,sep!A2:D1958,4,0) -> 30 | K2: M | L2: 01/Aug/2020 | M2: Manpower Field | N2: Airtel NMT | O2: Patroller | P2: Regular | R2: Y | V2: 101395422287 | W2: 3011975588 | X2: AOQPJ8659C | Y2: 837982877164 | Z2: kushwahajitendra159@gmail.com | AA2: '51110226491 | AD2: SBIN0031891 | AG2: 7905630223 | AL2: Employee | AM2: N | AN2: N | AO2: N
A3: 10001 | B3: Indra Pratap Singh | C3: Dharmpal Singh | E3: 01/Jan/1984 | F3: Raipur Gadhi, Sadhira Ajgain, Unnao, Uttarpardesh | G3: Kanpur | H3: 9792964257 | I3: =VLOOKUP(A3,sep!A3:D1959,4,0) -> 30 | K3: M | L3: 01/Aug/2020 | M3: Manpower Field | N3: Airtel NMT | O3: Patroller | P3: Regular | R3: Y | V3: 101395421906 | W3: 3011992876 | X3: LEIPS0208B | Y3: 931959493430 | Z3: mithunsingh1754@gmail.com | AA3: '17892413001035 | AD3: ORBC0101789 | AG3: 7018992976 | AL3: Employee | AM3: N | AN3: N | AO3: N
A4: 10002 | B4: Alok Kumar | C4: Rajkumar | E4: 15/Jun/1992 | F4: 24, Baripur, Kanpur Nagar, Uttar Pradesh 209206 | G4: Kanpur | H4: 8840902651 | I4: =VLOOKUP(A4,sep!A2:D1958,4,0) -> 30 | K4: M | L4: 01/Aug/2020 | M4: Manpower Field | N4: Airtel NMT | O4: Patroller | P4: Regular | R4: Y | V4: 101279372719 | W4: 3011992865 | X4: FORPK8755L | Y4: 351485151314 | Z4: aloksing988@gmail.com | AA4: '50048100000064 | AD4: BARB0UNNRAE | AG4: 9354789371 | AL4: Employee | AM4: N | AN4: N | AO4: N
A5: 10003 | B5: Dileep Kumar | C5: Mukharam Singh | E5: 01/Dec/1997 | F5: Ragoli, Rahiya, Jalaun, Uttar Pradesh 285001 | G5: Kanpur | H5: 8756549991 | I5: =VLOOKUP(A5,sep!A5:D1961,4,0) -> 30 | K5: M | L5: 01/Aug/2020 | M5: Manpower Field | N5: Airtel NMT | O5: Patroller | P5: Regular | R5: Y | V5: 101519867877 | W5: 6930665428 | X5: IQPPK4721K | Y5: 497921532441 | Z5: dileepkumarragauli@gmail.com | AA5: '50100285504952 | AD5: HDFC0000406 | AG5: 9129216367 | AL5: Employee | AM5: N | AN5: N | AO5: N
A6: 10004 | B6: Brijendra Singh | C6: Dharmpal Singh | E6: 01/Aug/1988 | F6: Ward Number 08, Om Nagar, Jhinjhak, Kanpur Dehat, Uttar Pradesh 209302 | G6: Kanpur | H6: 7897677595 | I6: =VLOOKUP(A6,sep!A6:D1962,4,0) -> 30 | K6: M | L6: 01/Aug/2020 | M6: Manpower Field | N6: Airtel NMT | O6: Patroller | P6: Regular | R6: Y | V6: 101372116048 | W6: 3011992795 | X6: FFHPS0541K | Y6: 245658088237 | Z6: N/A | AA6: '20390200844 | AD6: SBIN0006589 | AG6: 7275308082 | AL6: Employee | AM6: N | AN6: N | AO6: N
A7: 10005 | B7: Bharat Prasad | C7: Sundra Lal | E7: 24/Dec/1987 | F7: Sangauli, Jhansi, Patha, Uttar Pradesh 284302 | G7: Kanpur | H7: 8840863098 | I7: =VLOOKUP(A7,sep!A5:D1961,4,0) -> 30 | K7: M | L7: 01/Aug/2020 | M7: Manpower Field | N7: Airtel NMT | O7: Patroller | P7: Regular | R7: Y | V7: 101395413303 | W7: 3011992801 | X7: CRTPP4558A | Y7: 740156874153 | Z7: bp037186@gmail.com | AA7: '2223000400009745 | AD7: PUNB0222300 | AG7: 8173897889 | AL7: Employee | AM7: N | AN7: N | AO7: N
A8: 10006 | B8: Ganesh | C8: Sukram | E8: 01/Jan/1978 | F8: 128, Lalle Ki Toriya, Baruasagar, Phutera Baruwa Sagar, Jhansi, Uttar Pradesh 284201 | G8: Kanpur | H8: 8318466132 | I8: =VLOOKUP(A8,sep!A8:D1964,4,0) -> 30 | K8: M | L8: 01/Aug/2020 | M8: Manpower Field | N8: Airtel NMT | O8: Patroller | P8: Regular | R8: Y | V8: 101440706183 | W8: 3011992802 | X8: CPHPG2136M | Y8: 563578117790 | Z8: ganeshganeshg567@gmail.com | AA8: '1321000100167033 | AD8: PUNB0132100 | AG8: 9616518998 | AL8: Employee | AM8: N | AN8: N | AO8: N
A9: 10007 | B9: Digvijay Singh | C9: Chheda Lal | E9: 25/Apr/1992 | F9: E 27, Tehsil Hamirpur, Uttar Pradesh 210301 | G9: Kanpur | H9: 9621390808 | I9: =VLOOKUP(A9,sep!A7:D1963,4,0) -> 30 | K9: M | L9: 01/Aug/2020 | M9: Manpower Field | N9: Airtel NMT | O9: Patroller | P9: Regular | R9: Y | V9: 101395420208 | W9: 3011992872 | X9: CSHPS3724G | Y9: 421358133513 | Z9: digvijay.8989@gmail.com | AA9: '30807530132 | AD9: SBIN0000089 | AG9: 9532936921 | AL9: Employee | AM9: N | AN9: N | AO9: N
A10: 10008 | B10: Anoop Kumar | C10: Rajender Kumar | E10: 02/Jul/1996 | F10: 120, Bangla Paras, Ghatampur, Kanpur Nagar, Uttar Pradesh 209206 | G10: Kanpur | H10: 7881177664 | I10: =VLOOKUP(A10,sep!A2:D1958,4,0) -> 30 | K10: M | L10: 01/Aug/2020 | M10: Manpower Field | N10: Airtel NMT | O10: Patroller | P10: Regular | R10: Y | V10: 101453109807 | W10: 3011992869 | X10: DYTPK5152H | Y10: 529313624018 | Z10: anoopyadav77387@gmail.com | AA10: '34999789618 | AD10: SBIN0001057 | AG10: 7080142034 | AL10: Employee | AM10: N | AN10: N | AO10: N
A11: 10009 | B11: Jagdeesh Kumhar | C11: Khachore Kumhar | E11: 02/Apr/1984 | F11: Ward Number 12 Chadrapura Khas, Naguwan, Tikamgarh, Madhya Pradesh 472338 | G11: Kanpur | H11: 9770025694 | I11: =VLOOKUP(A11,sep!A11:D1967,4,0) -> 30 | K11: M | L11: 01/Aug/2020 | M11: Manpower Field | N11: Airtel NMT | O11: Patroller | P11: Regular | R11: Y | V11: 101601758063 | W11: 6930665500 | X11: JTJPK6448H | Y11: 558477543202 | Z11: jagadisakumhara301@gmail.com | AA11: '38938100039705 | AD11: BARB0TIKAMG | AG11: 6261215020 | AL11: Employee | AM11: N | AN11: N | AO11: N
A12: 10010 | B12: Kailash Kushwaha | C12: Bhagvan Das Kushwaha | E12: 13/Dec/1993 | F12: Ward Number 36, Jhansi Road Ramnagar,Datia, Mp 475661 | G12: Kanpur | H12: 7869357589 | I12: =VLOOKUP(A12,sep!A12:D1968,4,0) -> 30 | K12: M | L12: 01/Aug/2020 | M12: Manpower Field | N12: Airtel NMT | O12: Patroller | P12: Regular | R12: Y | V12: 101395428433 | W12: 3011992822 | X12: GNQPK9235J | Y12: 248462106261 | Z12: kailashkushwaha173@gmail.com | AA12: '50265191852 | AD12: ALLA0213299 | AG12: 7898756171 | AL12: Employee | AM12: N | AN12: N | AO12: N
A13: 10011 | B13: Satyam Kumar | C13: Shashi Bhushan Prasad Singh | E13: 22/Nov/1982 | F13: Village Post Office Manjhaul, Begusarai, Bihar 851127 | G13: Kanpur | H13: 9076987980 | I13: =VLOOKUP(A13,sep!A13:D1969,4,0) -> 30 | K13: M | L13: 01/Aug/2020 | M13: Manpower Field | N13: Airtel NMT | O13: Patroller | P13: Regular | R13: Y | V13: 101397716141 | W13: 3011992874 | X13: DWXPK7085P | Y13: 557401958734 | Z13: satyamhmr@gmail.com | AA13: '31435089826 | AD13: SBIN0000089 | AG13: 8423936683 | AL13: Employee | AM13: N | AN13: N | AO13: N
A14: 10012 | B14: Manoj | C14: Rakesh Nayak | E14: 18/Jul/1989 | F14: 165, Gram Sangoli, Jhansi, Uttar Pradesh 284302 | G14: Kanpur | H14: 9621881805 | I14: =VLOOKUP(A14,sep!A14:D1970,4,0) -> 30 | K14: M | L14: 01/Aug/2020 | M14: Manpower Field | N14: Airtel NMT | O14: Patroller | P14: Regular | R14: Y | V14: 101440719772 | W14: 3011992804 | X14: ASFPN8636E | Y14: 232350233365 | Z14: nayak.manoj057@gmail.com | AA14: '32738262698 | AD14: SBIN0000102 | AG14: 7460981942 | AL14: Employee | AM14: N | AN14: N | AO14: N
A15: 10013 | B15: Anil Singh | C15: Rajendra Singh | E15: 17/May/1977 | F15: Village & Post Office Nasada, Nasara, Kanpur Nagar, Uttar Pradesh 209401 | G15: Kanpur | H15: 9935030139 | I15: =VLOOKUP(A15,sep!A2:D1958,4,0) -> 30 | K15: M | L15: 01/Aug/2020 | M15: Manpower Field | N15: Airtel NMT | O15: Patroller | P15: Regular | R15: Y | V15: 101594069566 | W15: 6930665549 | X15: MGCPS5525G | Y15: 745896054804 | Z15: as7778774@gmail.com | AA15: '1890000100066511 | AD15: PUNB0189000 | AG15: 9621254600 | AL15: Employee | AM15: N | AN15: N | AO15: N
A16: 10014 | B16: Ranjdeep Singh Bundela | C16: Manohar Singh Bundela | E16: 01/Jan/1991 | F16: Chhipai, Pipra Raipur, Lalitpur, Talbehat Uttar Pradesh 284124 | G16: Kanpur | H16: 9452212121 | I16: =VLOOKUP(A16,sep!A16:D1972,4,0) -> 30 | K16: M | L16: 01/Aug/2020 | M16: Manpower Field | N16: Airtel NMT | O16: Patroller | P16: Regular | R16: Y | V16: 101440721537 | W16: 3011992809 | X16: CPVPB4800D | Y16: 491472074486 | Z16: rajdeepraja2020@gmail.com | AA16: '7739001700003858 | AD16: PUNB0773900 | AG16: 7007593070 | AL16: Employee | AM16: N | AN16: N | AO16: N
A17: 10015 | B17: Gyan Singh | C17: Shree Babu | E17: 04/Jul/1995 | F17: Baraur, Kanpur, Dehat, Bhognipur, Uttar Pradesh 209312 | G17: Kanpur | H17: 9598641435 | I17: =VLOOKUP(A17,sep!A9:D1965,4,0) -> 30 | K17: M | L17: 01/Aug/2020 | M17: Manpower Field | N17: Airtel NMT | O17: Patroller | P17: Regular | R17: Y | V17: 101363344216 | W17: 6930672414 | X17: IKQPS2580P | Y17: 432961873616 | Z17: gyansinghsharma39482@gmail.com | AA17: '38146903969 | AD17: SBIN0001093 | AG17: 8934814123 | AL17: Employee | AM17: N | AN17: N | AO17: N
A18: 10016 | B18: Pinku | C18: Dinesh | E18: 09/Sep/1989 | F18: 9, Dirgaj Khera, Ajgain, Unnao, Uttar Pradesh 209801 | G18: Kanpur | H18: 9260999901 | I18: =VLOOKUP(A18,sep!A18:D1974,4,0) -> 30 | K18: M | L18: 01/Aug/2020 | M18: Manpower Field | N18: Airtel NMT | O18: Patroller | P18: Regular | R18: Y | V18: 101440721954 | W18: 3011996921 | X18: Nill | Y18: 825750016477 | Z18: pinkuyadav9989@gmail.com | AA18: '133400101003862 | AD18: CORP0001334 | AG18: 9794732351 | AL18: Employee | AM18: N | AN18: N | AO18: N
A19: 10017 | B19: Dinesh Pal | C19: Dhaniram | E19: 16/Apr/1986 | F19: Nagra, Post Office Bhevli, Sarsaul, Kanpur Nagar, Uttar Pradesh 209402 | G19: Kanpur | H19: 9794217635 | I19: =VLOOKUP(A19,sep!A6:D1962,4,0) -> 30 | K19: M | L19: 01/Aug/2020 | M19: Manpower Field | N19: Airtel NMT | O19: Patroller | P19: Regular | R19: Y | V19: 101088721474 | W19: 6930665700 | X19: CKRPP0166M | Y19: 941295867317 | Z19: dinesh4536ad@gmail.com | AA19: '30725586236 | AD19: SBIN0011817 | AG19: 9918244018 | AL19: Employee | AM19: N | AN19: N | AO19: N
A20: 10018 | B20: Prashant Pal | C20: Siyaram Pal | E20: 01/Jan/1990 | F20: 165, Bhadwara Aashik, Bhadwara, Kanpur Nagar, Ghatampur Uttar Pradesh 209206 | G20: Kanpur | H20: 7355740674 | I20: =VLOOKUP(A20,sep!A18:D1974,4,0) -> 30 | K20: M | L20: 01/Aug/2020 | M20: Manpower Field | N20: Airtel NMT | O20: Patroller | P20: Regular | R20: Y | V20: 101279372726 | W20: 3011992862 | X20: CDGPP0969L | Y20: 379351351632 | Z20: prashantpa970@gmail.com | AA20: '32685559530 | AD20: SBIN0001874 | AG20: 9519675425 | AL20: Employee | AM20: N | AN20: N | AO20: N
A21: 10019 | B21: Rajesh Pal | C21: Shiv Raj | E21: 20/Aug/1991 | F21: Daulatpur Narvai, Post Office Saad, Ghatampur, Kanpur, Nagpur, Uttar Pradesh 209206 | G21: Kanpur | H21: 8795959124 | I21: =VLOOKUP(A21,sep!A19:D1975,4,0) -> 30 | K21: M | L21: 01/Aug/2020 | M21: Manpower Field | N21: Airtel NMT | O21: Patroller | P21: Regular | R21: Y | V21: 101279372735 | W21: 3011992860 | X21: CLPPP0374N | Y21: 374283438039 | Z21: pal3728492gmail.com | AA21: '33181473033 | AD21: SBIN0012321 | AG21: 7355388772 | AL21: Employee | AM21: N | AN21: N | AO21: N
A22: 10020 | B22: Ravindra Kumar Vishwakarma | C22: Baldev Vishwakarma | E22: 01/Apr/1974 | F22: House Number 917, Gram Khadi Gporihar, Dhadari, Chhatarpur, Madhya Pradesh 471001 | G22: Kanpur | H22: 9993614151 | I22: =VLOOKUP(A22,sep!A22:D1978,4,0) -> 30 | K22: M | L22: 01/Aug/2020 | M22: Manpower Field | N22: Airtel NMT | O22: Patroller | P22: Regular | R22: Y | V22: 101521508586 | W22: 3011992832 | X22: ARZPV3360J | Y22: 652222858063 | Z22: ravindrvishwakarma555@gmail.com | AA22: '31447394610 | AD22: SBIN0002873 | AG22: 8085568606 | AL22: Employee | AM22: N | AN22: N | AO22: N
A23: 10022 | B23: Shailendra Kumar Yadav | C23: Ramswaroop Yadav | E23: 11/Jul/1986 | F23: Magrasa, Ramaipur, Kanpur Nagar, Uttar Pradesh 209214 | G23: Kanpur | H23: 8853779058 | I23: =VLOOKUP(A23,sep!A23:D1979,4,0) -> 30 | K23: M | L23: 01/Aug/2020 | M23: Manpower Field | N23: Airtel NMT | O23: Patroller | P23: Regular | R23: Y | V23: 101395439567 | W23: 3011992867 | X23: APMPY7624K | Y23: 887288071923 | Z23: shailendrakanpur123@gmail.com | AA23: '36285477196 | AD23: SBIN0016994 | AG23: 6389615187 | AL23: Employee | AM23: N | AN23: N | AO23: N
A24: 10023 | B24: Kailash Singh | C24: Shambhu Dyal Yadav | E24: 20/Jul/1989 | F24: Village Chhani Bujurg, District Hamidpur, Uttar Pradesh 210501 | G24: Kanpur | H24: 7905954491 | I24: =VLOOKUP(A24,sep!A16:D1972,4,0) -> 30 | K24: M | L24: 01/Aug/2020 | M24: Manpower Field | N24: Airtel NMT | O24: Patroller | P24: Regular | R24: Y | V24: 100185505854 | W24: 3011992812 | X24: EFMPS2594C | Y24: 467903613680 | Z24: ks8021883@gmail.com | AA24: '32394344296 | AD24: SBIN0009691 | AG24: 9670768760 | AL24: Employee | AM24: N | AN24: N | AO24: N
A25: 10084 | B25: Hitesh | C25: Katar Singh | E25: 15/Jun/1995 | F25: Rampur, Muzaffarnagar, Uttar Pradesh 251001 | G25: Meerut | H25: 8077954034 | I25: =VLOOKUP(A25,sep!A48:D1981,4,0) -> 30 | K25: M | L25: 01/Aug/2020 | M25: Manpower Field | N25: Airtel NMT | O25: Patroller | P25: Regular | R25: Y | V25: 100471002888 | W25: 3012215469 | X25: APAPH3511G | Y25: 551199442781 | Z25: nk786690@gmail.com | AA25: '2289877589 | AD25: CBIN0282202 | AG25: 9627345944 | AL25: Employee | AM25: N | AN25: N | AO25: N
A26: 10085 | B26: Munidev | C26: Ramesh | E26: 20/Sep/1988 | F26: Village Khyalipur, Gajraula, Amroha, Uttar Pradesh 244235 | G26: Meerut | H26: 8171891916 | I26: =VLOOKUP(A26,sep!A49:D1982,4,0) -> 30 | K26: M | L26: 01/Aug/2020 | M26: Manpower Field | N26: Airtel NMT | O26: Patroller | P26: Regular | R26: Y | V26: 101219704095 | W26: 3012215519 | X26: DLJPM0430H | Y26: 801769308916 | Z26: devmuni81@gmail.com | AA26: '1775000100235399 | AD26: PUNB0177500 | AG26: 8218586919 | AL26: Employee | AM26: N | AN26: N | AO26: N
A27: 10086 | B27: Guddu Singh | C27: Hari Singh | E27: 05/Jan/1985 | F27: Near Parivartan School, Pital Nagari Suraj Nagar, Moradabad, Uttar Pradesh 244001 | G27: Meerut | H27: 8171651193 | I27: =VLOOKUP(A27,sep!A50:D1983,4,0) -> 30 | K27: M | L27: 01/Aug/2020 | M27: Manpower Field | N27: Airtel NMT | O27: Patroller | P27: Regular | R27: Y | V27: 100997187987 | W27: 3012215366 | X27: ELMPS8370A | Y27: 620277156654 | Z27: guddusingh847415@gmail.com | AA27: '780410110001333 | AD27: BKID0007804 | AG27: 9927221106 | AL27: Employee | AM27: N | AN27: N | AO27: N
A28: 10088 | B28: Omveer (Avneesh) | C28: Natthu Singh | E28: 01/Jan/1982 | F28: Kakrali, Dado, Aligarh, Uttar Pradesh 202133 | G28: Meerut | H28: 8126029642 | I28: =VLOOKUP(A28,sep!A51:D1984,4,0) -> 30 | K28: M | L28: 01/Aug/2020 | M28: Manpower Field | N28: Airtel NMT | O28: Patroller | P28: Regular | R28: Y | V28: 101422460833 | W28: 3012215465 | X28: ADEPO3525D | Y28: 828929341852 | Z28: avinishkumar8048@gmail.com | AA28: '35641300325 | AD28: SBIN0018577 | AG28: 9758538226 | AL28: Employee | AM28: N | AN28: N | AO28: N
A29: 10089 | B29: Manoj Kumar | C29: Shripal Singh | E29: 03/Jun/1990 | F29: Khera, Meerat, Uttar Pradesh 250342 | G29: Meerut | H29: 9557961805 | I29: =VLOOKUP(A29,sep!A52:D1985,4,0) -> 30 | K29: M | L29: 01/Aug/2020 | M29: Manpower Field | N29: Airtel NMT | O29: Patroller | P29: Regular | R29: Y | V29: 101340708288 | W29: 3012215478 | X29: ESNPK6681J | Y29: 316229444667 | Z29: manojsolukhera@gmail.com | AA29: '32890782824 | AD29: SBIN0000713 | AG29: 8077615840 | AL29: Employee | AM29: N | AN29: N | AO29: N
A30: 10090 | B30: Daulat Singh | C30: Amar Singh | E30: 20/Jun/1970 | F30: M.D.A Colony, Gajraula, Dhanaura Amroha, District Gajraula, State Uttar Pradesh 244235 | G30: Meerut | H30: 9760946683 | I30: =VLOOKUP(A30,sep!A53:D1986,4,0) -> 30 | K30: M | L30: 01/Aug/2020 | M30: Manpower Field | N30: Airtel NMT | O30: Patroller | P30: Regular | R30: Y | V30: 101181524592 | W30: 3012093343 | X30: AVPPD9338J | Y30: 614313004045 | Z30: daulatsingh40842@gmail.com | AA30: '31232066343 | AD30: SBIN0007691 | AG30: 9997238501 | AL30: Employee | AM30: N | AN30: N | AO30: N
A31: 10091 | B31: Prem Pal Singh | C31: Gulaveer Singh | E31: 10/Nov/1985 | F31: Hajaratpur Poothari, Post Office Agaura Amirpur, Bulandshahr, Hameerpur, Uttar Pradesh 203131 | G31: Meerut | H31: 9411859730 | I31: =VLOOKUP(A31,sep!A54:D1987,4,0) -> 30 | K31: M | L31: 01/Aug/2020 | M31: Manpower Field | N31: Airtel NMT | O31: Patroller | P31: Regular | R31: Y | V31: 100280893818 | W31: 3012215397 | X31: CBIPS4407A | Y31: 770282026623 | Z31: guddubsnlkrj@gmail.com | AA31: '21715813588 | AD31: ALLA0211967 | AG31: 8923363922 | AL31: Employee | AM31: N | AN31: N | AO31: N
A32: 10092 | B32: Raghav Sagar (Rinku) | C32: Suresh Sagar | E32: 07/Jul/1988 | F32: 169, Dasva Ghat Near Nagfani Thana, Moradabad, Thakurwada, Uttarpradesh 244001 | G32: Meerut | H32: 8077363612 | I32: =VLOOKUP(A32,sep!A55:D1988,4,0) -> 30 | K32: M | L32: 01/Aug/2020 | M32: Manpower Field | N32: Airtel NMT | O32: Patroller | P32: Regular | R32: Y | V32: 100530813157 | W32: 3012092000 | X32: CKHPS4791P | Y32: 512344282719 | Z32: sagarrinku63@gmail.com | AA32: '6212064588 | AD32: KKBK0005300 | AG32: 9012615365 | AL32: Employee | AM32: N | AN32: N | AO32: N
A33: 10093 | B33: Kailash Kumar | C33: Ganga Saran | E33: 01/Jan/1992 | F33: Ward Number 8, Avanti Nagar, Bhoor, Bulandshahr, Uttar Pradesh 203001 | G33: Meerut | H33: 7455805676 | I33: =VLOOKUP(A33,sep!A56:D1989,4,0) -> 30 | K33: M | L33: 01/Aug/2020 | M33: Manpower Field | N33: Airtel NMT | O33: Patroller | P33: Regular | R33: Y | V33: 101340763619 | W33: 3012215510 | X33: ETCPK5940Q | Y33: 503802452342 | Z33: kailash9234kumar@gmail.com | AA33: '3357001700162319 | AD33: PUNB0335700 | AG33: 7830752564 | AL33: Employee | AM33: N | AN33: N | AO33: N
A34: 10094 | B34: Buland Kumar | C34: Prakash Chand | E34: 01/Jan/1982 | F34: Village & Post Office Sakoti Tanda, Jasrathpur, Meerat, Sardhana, Uttar Pradesh 250342 | G34: Meerut | H34: 8273493434 | I34: =VLOOKUP(A34,sep!A57:D1990,4,0) -> 30 | K34: M | L34: 01/Aug/2020 | M34: Manpower Field | N34: Airtel NMT | O34: Patroller | P34: Regular | R34: Y | V34: 100118036413 | W34: 3012215457 | X34: HCAPK6174A | Y34: 293898083404 | Z34: Bukandsing6815@gimall.com | AA34: '31920006879 | AD34: SBIN0002469 | AG34: 7037779271 | AL34: Employee | AM34: N | AN34: N | AO34: N
A35: 10095 | B35: Manveer Singh Yadav | C35: Gajendra Singh Yadav | E35: 01/Jan/1988 | F35: 44, Agapur, Rampur City, Rampur, Uttar Pradesh 244901 | G35: Meerut | H35: 7895748300 | I35: =VLOOKUP(A35,sep!A58:D1991,4,0) -> 30 | K35: M | L35: 01/Aug/2020 | M35: Manpower Field | N35: Airtel NMT | O35: Patroller | P35: Regular | R35: Y | V35: 101340708261 | W35: 3012215443 | X35: AVXPY0710F | Y35: 746420647754 | Z35: Yadavmanveersingh90@gmail.com | AA35: '33685448867 | AD35: SBIN0014898 | AG35: 9536068334 | AL35: Employee | AM35: N | AN35: N | AO35: N
A36: 10096 | B36: Chandravir | C36: Rajinder Singh | E36: 01/Jan/1976 | F36: Khera, Khas Sarthal, Sambhal, Chandausi, State Uttar Pradesh 202414 | G36: Meerut | H36: 9634694075 | I36: =VLOOKUP(A36,sep!A59:D1992,4,0) -> 30 | K36: M | L36: 01/Aug/2020 | M36: Manpower Field | N36: Airtel NMT | O36: Patroller | P36: Regular | R36: Y | V36: 101342442682 | W36: 3012215453 | X36: BFRPC6184A | Y36: 237736905325 | Z36: chandraveersingh65123@gmail.com | AA36: '0094000102024127 | AD36: PUNB0009400 | AG36: 9759609498 | AL36: Employee | AM36: N | AN36: N | AO36: N
... A79: 10255 | B79: Shushil Tiwari | C79: Rajjain Tiwari | E79: 03/Apr/2000 | F79: Village Himmatpur Post Shingpur Tehsil,Chandla,District,Chatarpur,M.P 471525 | G79: CHHATARPUR | H79: 6261915661 | I79: =VLOOKUP(A79,sep!A102:D2035,4,0) -> 30 | K79: M | L79: 01/Aug/2020 | M79: Manpower Field | N79: Airtel NMT | O79: Patroller | P79: Regular | R79: Y | V79: 101603146878 | W79: 6930669789 | X79: BVOPT1382E | Y79: 217416568430 | Z79: st703730@gmail.com | AA79: '39191928848 | AD79: SBIN0002839 | AG79: 7828428914 | AL79: Employee | AM79: N | AN79: N | AO79: N
A80: 10274 | B80: D.Raj Kiran | C80: Sh.D.Balakrishna | E80: 07/Jun/1984 | F80: House Number 4-23, Plot Number 19, Kranthi Colony, Medipally Uppal Depot, Ghatkesar Mandal, Andhra Pradesh | G80: MOHALI | H80: 9160029966 | I80: =VLOOKUP(A80,sep!A103:D2036,4,0) -> 30 | J80: rajkiran@horizontelecom.in | K80: M | L80: 24/Aug/2020 | M80: Manpower Field | N80: Human Resource | O80: Supervisor | R80: Y | S80: N | T80: 4036 | U80: Ram Pal | X80: AKQPD2857C | Y80: 762043098512 | Z80: rajkiran@horizontelecom.in | AA80: '00000020097622816 | AD80: SBIN0021927 | AG80: 9000134076 | AK80: rajkiran@horizontelecom.in | AL80: Employee | AM80: Y | AN80: N | AO80: N
A81: 10275 | B81: Udayveer | C81: Jandel Singh | E81: 01/Jan/1983 | F81: Village Lakhotikala,Post Office,Lakhotikala District Gwalior M.P475001 | G81: GWALIOR | H81: 9754045865 | I81: =VLOOKUP(A81,sep!A104:D2037,4,0) -> 30 | K81: M | L81: 01/Aug/2020 | M81: Manpower Field | N81: Airtel NMT | O81: Patroller | P81: Regular | R81: Y | V81: 101603147133 | W81: 6930669793 | X81: AFCPU4578C | Y81: 257125882215 | Z81: Gurjarudayveer06@gmail.com | AA81: '2964000105129755 | AD81: PUNB0296400 | AG81: Nil | AL81: Employee | AM81: N | AN81: N | AO81: N
A82: 10277 | B82: Sushil Gupta | C82: Jugul Kishor Gupta | E82: 11/Aug/1998 | F82: Ward No.08,Daldal,Kapildhara Road Bijuri,District Shahdol.M.P 484440 | G82: CHHATARPUR | H82: 9399723854 | I82: =VLOOKUP(A82,sep!A105:D2038,4,0) -> 30 | K82: M | L82: 01/Aug/2020 | M82: Manpower Field | N82: Airtel NMT | O82: Patroller | P82: Regular | R82: Y | V82: 101603147179 | W82: 6930669796 | X82: CENPG0117B | Y82: 359872340182 | Z82: sushilguptagupta35@gmail.com | AA82: '30725239623 | AD82: SBIN0006072 | AG82: 8516022388 | AL82: Employee | AM82: N | AN82: N | AO82: N
...
